Workbook

Sheet Gesamtplanung
A1: Details | B1: Total | C1: PCGB | D1: PD | E1: PKO | F1: POF | G1: PIT | H1: TRK | I1: PCL | J1: PIB SPA | K1: PNO | L1: PIB POR | M1: PCH | N1: PTW | O1: PCA | P1: PPL | Q1: PJ | R1: PBR | S1: PCNA
A2: CPL | B2: Macan BEV | C2: 1586 | D2: 2782 | E2: - | F2: 2109 | G2: 715 | H2: 403 | I2: 7059 | J2: 3577 | K2: 3964 | L2: 896 | M2: 4951 | O2: 4904 | P2: - | Q2: - | S2: -
B3: Cayenne E3 II | C3: 1245 | D3: 1499 | E3: 1069 | F3: - | G3: 2356 | H3: - | I3: 2145 | J3: 4133 | K3: - | L3: - | M3: - | N3: - | O3: 2540 | P3: 4290 | Q3: - | R3: - | S3: 916
B4: 25% von CTG | C4: =(AVERAGE(C2,C3))/4 -> 353.875 | D4: =(AVERAGE(D2,D3))/4 -> 535.125 | E4: =(AVERAGE(E2,E3))/4 -> 267.25 | F4: =(AVERAGE(F2,F3))/4 -> 527.25 | G4: =(AVERAGE(G2,G3))/4 -> 383.875 | H4: =(AVERAGE(H2,H3))/4 -> 100.75 | I4: =(AVERAGE(I2,I3))/4 -> 1150.5 | J4: =(AVERAGE(J2,J3))/4 -> 963.75 | ... M4: =(AVERAGE(M2,M3))/4 -> 1237.75 | N4: =272/4 -> 68 | O4: =(AVERAGE(O2,O3))/4 -> 930.5 | P4: =(AVERAGE(P2,P3))/4 -> 1072.5 | Q4: =AVERAGE(C4:P4,S4) -> 602.34167 | R4: =AVERAGE(C4:Q4,S4) -> 602.34167 | S4: =(AVERAGE(S2,S3))/4 -> 229 | T4: =(AVERAGE(T2,T3))/2 -> #DIV/0! | U4: =(AVERAGE(U2,U3))/2 -> #DIV/0! | V4: =(AVERAGE(V2,V3))/2 -> #DIV/0!
B5: Macan BEV (25%) | C5: =C2/4 -> 396.5 | D5: =D2/4 -> 695.5 | E5: =E4 -> 267.25 | F5: =F2/4 -> 527.25 | G5: =G2/4 -> 178.75 | H5: =H2/4 -> 100.75 | I5: =I2/4 -> 1764.75 | J5: =J2/4 -> 894.25 | K5: =K2/4 -> 991 | L5: =L2/4 -> 224 | M5: =M2/4 -> 1237.75 | ... O5: =O2/4 -> 1226 | P5: =P3/4 -> 1072.5 | S5: =AVERAGE(C5:P5) -> 684.01786
B6: Cayenne E3 II (25%) | C6: =C3/4 -> 311.25 | D6: =D3/4 -> 374.75 | E6: =E3/4 -> 267.25 | F6: =F4 -> 527.25 | G6: =G3/4 -> 589 | H6: =H4 -> 100.75 | I6: =I3/4 -> 536.25 | J6: =J3/4 -> 1033.25 | K6: =K4 -> 991 | L6: =L4 -> 224 | M6: =M4 -> 1237.75 | N6: 0 | O6: =O3/4 -> 635 | P6: =P3/4 -> 1072.5 | S6: =S3/4 -> 229
B7: Cayenne E4 (25%) | C7: =AVERAGE(C2:C3)/4 -> 353.875 | D7: =AVERAGE(D2:D3)/4 -> 535.125 | E7: =AVERAGE(E2:E3)/4 -> 267.25 | F7: =AVERAGE(F2:F3)/4 -> 527.25 | G7: =AVERAGE(G2:G3)/4 -> 383.875 | H7: =AVERAGE(H2:H3)/4 -> 100.75 | I7: =AVERAGE(I2:I3)/4 -> 1150.5 | J7: =AVERAGE(J2:J3)/4 -> 963.75 | ... M7: =AVERAGE(M2:M3)/4 -> 1237.75 | N7: =AVERAGE(E7,H7,L7,R7,S7) -> 205.25 | O7: =AVERAGE(O2:O3)/4 -> 930.5 | P7: =AVERAGE(P2:P3)/4 -> 1072.5 | S7: =AVERAGE(S2:S3)/4 -> 229
A8: Planned sales | B8: Macan BEV | C8: 5457 | D8: 4700 | E8: 1500 | F8: 1607 | G8: 1655 | H8: 388 | I8: 606 | J8: =1100*0.7 -> 770 | K8: 629 | L8: =J8/0.7*0.3 -> 330 | M8: 658 | N8: 573 | O8: 563 | P8: 374 | Q8: 862 | R8: 1356 | S8: 5358
B9: Cayenne E3 II | C9: 2622 | D9: 3800 | E9: 826 | F9: 450 | G9: 1920 | H9: 136 | I9: 2242 | J9: =1178*0.7 -> 824.6 | K9: 19 | L9: =J9/0.7*0.3 -> 353.4 | M9: 738 | N9: 1348 | O9: 1679 | P9: 1366 | Q9: 586 | R9: 1760 | S9: 20820
B10: Cayenne E4 | C10: 2068 | D10: 2200 | E10: 2000 | F10: 800 | G10: 410 | H10: 383 | I10: 298 | J10: =800*0.7 -> 560 | K10: 529 | L10: =J10/0.7*0.3 -> 240 | M10: 328 | N10: 535 | O10: 368 | P10: 218 | Q10: 357 | R10: 295 | S10: 3440 | U10: PIB SPA | V10: PIB POR | W10: =SUM(C10:S10)-S10 -> 11589 | X10: =SUM(SUM(C10:V10)) -> 15029 | Y10: =X10/X14 -> 1 | Z10: =Y10+#REF!/2 -> #REF! | AA10: =W10-H10 -> 11206
A11: Planned sales from media | B11: Macan BEV | C11: =C8*$C$20 -> 818.55 | D11: =D8*$C$20 -> 705 | E11: =E8*$C$20 -> 225 | F11: =F8*$C$20 -> 241.05 | G11: =G8*$C$20 -> 248.25 | H11: =H8*$C$20 -> 58.2 | I11: =I8*$C$20 -> 90.9 | J11: =J8*$C$20 -> 115.5 | ... S11: =S8*$C$20 -> 803.7
B12: Cayenne E3 II | C12: =C9*$C$20 -> 393.3 | D12: =D9*$C$20 -> 570 | E12: =E9*$C$20 -> 123.9 | F12: =F9*$C$20 -> 67.5 | G12: =G9*$C$20 -> 288 | H12: =H9*$C$20 -> 20.4 | I12: =I9*$C$20 -> 336.3 | J12: =J9*$C$20 -> 123.69 | ... S12: =S9*$C$20 -> 3123
B13: Cayenne E4 | C13: =C10*$C$20 -> 310.2 | D13: =D10*$C$20 -> 330 | E13: =E10*$C$20 -> 300 | F13: =F10*$C$20 -> 120 | G13: =G10*$C$20 -> 61.5 | H13: =H10*$C$20 -> 57.45 | I13: =I10*$C$20 -> 44.7 | J13: =J10*$C$20 -> 84 | ... S13: =S10*$C$20 -> 516
A14: Currently planned market media budget 2026 | B14: Macan BEV | C14: =[1]Übersicht!$I$5 -> 532249.63 | D14: =[1]Übersicht!$I$9 -> 754400 | E14: =[1]Übersicht!$I$14 -> 0 | F14: =[1]Übersicht!$I$16 -> 0 | G14: =[1]Übersicht!$I$12 -> 202952 | H14: 0 | I14: =[1]Übersicht!$I$7 -> 314801.99 | J14: =[1]Übersicht!$I$11 -> 421000 | K14: =[1]Übersicht!$I$15 -> 143485.8 | L14: =[1]Übersicht!$I$10 -> 65010.76 | M14: =[1]Übersicht!$I$6 -> 32831.888 | N14: =[1]Übersicht!$I$18 -> 67638.043 | O14: =[1]Übersicht!$I$3 -> 470545.54 | P14: =[1]Übersicht!$I$17 -> 27761.577 | Q14: =[1]Übersicht!$I$13 -> 100338.83 | R14: =[1]Übersicht!$I$2 -> 26553.282 | S14: =[1]Übersicht!$I$8 -> 374048.77 | T14: =J16+L16 -> 200000 | U14: =J16/T14 -> 1 | V14: =L16/T14 -> 0 | X14: =SUM(SUM(X10:X10)) -> 15029
B15: Cayenne E3 II | C15: =[1]Übersicht!$E$5 -> 197311 | D15: =[1]Übersicht!$E$9 -> 477500 | E15: =[1]Übersicht!$E$14 -> 0 | F15: 0 | G15: =[1]Übersicht!$E$12 -> 0 | H15: 0 | I15: =[1]Übersicht!$E$7 -> 944405.97 | J15: =[1]Übersicht!$E$11 -> 150000 | K15: =[1]Übersicht!$E$15 -> 0 | L15: 0 | M15: =[1]Übersicht!$E$6 -> 9553.091 | N15: =[1]Übersicht!$E$18 -> 101502.17 | O15: =[1]Übersicht!$E$3 -> 711261.64 | P15: =[1]Übersicht!$E$17 -> 648664.41 | Q15: =[1]Übersicht!$E$13 -> 13662.695 | R15: =[1]Übersicht!$E$2 -> 47340.399 | S15: =[1]Übersicht!$E$8 -> 4042327.2
B16: Cayenne E4 | C16: =[1]Übersicht!$F$5 -> 379717.79 | D16: =[1]Übersicht!$F$9 -> 694200 | E16: =[1]Übersicht!$F$14 -> 1034179.3 | F16: =[1]Übersicht!$F$16 -> 200000 | G16: =[1]Übersicht!$F$12 -> 180144.48 | H16: =346667/3 -> 115555.67 | I16: =[1]Übersicht!$F$7 -> 245545.55 | J16: =[1]Übersicht!$F$11 -> 200000 | K16: =[1]Übersicht!$F$15 -> 110681.42 | L16: =[1]Übersicht!$F$10 -> 0 | M16: =[1]Übersicht!$F$6 -> 274074.89 | N16: =[1]Übersicht!$F$18 -> 86288.906 | O16: =[1]Übersicht!$F$3 -> 687673.88 | P16: =[1]Übersicht!$F$17 -> 845678.29 | Q16: =[1]Übersicht!$F$13 -> 230134.44 | R16: =[1]Übersicht!$F$2 -> 56232.027 | S16: =[1]Übersicht!$F$8 -> 210222.3
A17: Total media budget 2026 | C17: 3282787 | D17: 4220000 | E17: 1924837 | F17: 1388000 | G17: 1502000 | H17: 346667 | I17: 2679368 | J17: 851861 | K17: 647059 | L17: 350000 | M17: 1251505 | N17: 988533 | O17: 3395262 | P17: 1961839 | Q17: 1128085 | R17: 337000 | S17: 20612760 | T17: =SUM(C17:S17) -> 46867563
A18: Share of focus model lines in total media | C18: =(SUM(C14:C16)/C17) -> 0.33790752 | D18: =(SUM(D14:D16)/D17) -> 0.4564218 | E18: =(SUM(E14:E16)/E17) -> 0.5372815 | F18: =(SUM(F14:F16)/F17) -> 0.14409222 | G18: =(SUM(G14:G16)/G17) -> 0.25505758 | H18: =(SUM(H14:H16)/H17) -> 0.33333333 | I18: =(SUM(I14:I16)/I17) -> 0.56160763 | J18: =(SUM(J14:J16)/J17) -> 0.90507724 | ... S18: =(SUM(S14:S16)/S17) -> 0.22445312
A19: Difference to target value: 60% media in focus model lines | C19: =60%-C18 -> 0.26209248 | D19: =60%-D18 -> 0.1435782 | E19: =60%-E18 -> 0.062718496 | F19: =60%-F18 -> 0.45590778 | G19: =60%-G18 -> 0.34494242 | H19: =60%-H18 -> 0.26666667 | I19: =60%-I18 -> 0.038392371 | J19: =60%-J18 -> -0.30507724 | ... S19: =60%-S18 -> 0.37554688
A20: Target value share of planned sales influenced by media | C20: 0.15 | D20: 0.15 | E20: 0.15 | F20: 0.15 | G20: 0.15 | H20: 0.15 | I20: 0.15 | J20: 0.15 | K20: 0.15 | L20: 0.15 | M20: 0.15 | N20: 0.15 | O20: 0.15 | P20: 0.15 | Q20: 0.15 | R20: 0.15 | S20: 0.15 | T20: 0.2 | U20: 0.2 | V20: 0.2
A21: Lead to Sales Rate | C21: 0.26 | D21: 0.27 | E21: 0.19 | F21: 0.12 | G21: 0.12 | H21: 0.19 | I21: 0.36 | J21: 0.1 | K21: 0.12 | L21: 0.19 | M21: 0.19 | N21: 0.19 | O21: 0.12 | P21: 0.19 | Q21: 0.19 | R21: 0.19 | S21: 0.19 | W21: =AVERAGE(C21:S21) -> 0.18705882
A22: Required Leads (Total) | B22: Macan BEV | C22: =C11/C21 -> 3148.2692 | D22: =D11/D21 -> 2611.1111 | E22: =E11/E21 -> 1184.2105 | F22: =F11/F21 -> 2008.75 | G22: =G11/G21 -> 2068.75 | H22: =H11/H21 -> 306.31579 | I22: =I11/I21 -> 252.5 | J22: =J11/J21 -> 1155 | ... S22: =S11/S21 -> 4230 | W22: =SUM(C22:S22)-S22 -> 17503.591
B23: Cayenne E3 II | C23: =C12/C21 -> 1512.6923 | D23: =D12/D21 -> 2111.1111 | E23: =E12/E21 -> 652.10526 | F23: =F12/F21 -> 562.5 | G23: =G12/G21 -> 2400 | H23: =H12/H21 -> 107.36842 | I23: =I12/I21 -> 934.16667 | J23: =J12/J21 -> 1236.9 | ... S23: =S12/S21 -> 16436.842
B24: Cayenne E4 | C24: =C13/C21 -> 1193.0769 | D24: =D13/D21 -> 1222.2222 | E24: =E13/E21 -> 1578.9474 | F24: =F13/F21 -> 1000 | G24: =G13/G21 -> 512.5 | H24: =H13/H21 -> 302.36842 | I24: =I13/I21 -> 124.16667 | J24: =J13/J21 -> 840 | ... S24: =S13/S21 -> 2715.7895
A25: Required Media Budget | B25: Macan BEV | C25: =C22*C5 -> 1248288.8 | D25: =D22*D5 -> 1816027.8 | E25: =E22*E5 -> 316480.26 | F25: =F22*F5 -> 1059113.4 | G25: =G22*G5 -> 369789.06 | H25: =H22*H5 -> 30861.316 | I25: =I22*I5 -> 445599.37 | J25: =J22*J5 -> 1032858.8 | ... S25: =S22*S5 -> 2893395.5
B26: Cayenne E3 II | C26: =C23*C6 -> 470825.48 | D26: =D23*D6 -> 791138.89 | E26: =E23*E6 -> 174275.13 | F26: =F23*F6 -> 296578.12 | G26: =G23*G6 -> 1413600 | H26: =H23*H6 -> 10817.368 | I26: =I23*I6 -> 500946.88 | J26: =J23*J6 -> 1278026.9 | ... S26: =S23*S6 -> 3764036.8
B27: Cayenne E4 | C27: =C24*C7 -> 422200.1 | D27: =D24*D7 -> 654041.67 | E27: =E24*E7 -> 421973.68 | F27: =F24*F7 -> 527250 | G27: =G24*G7 -> 196735.94 | H27: =H24*H7 -> 30463.618 | I27: =I24*I7 -> 142853.75 | J27: =J24*J7 -> 809550 | ... S27: =S24*S7 -> 621915.79 | T27: =SUM(C25:S27) -> 29413676
A28: Budget gap for 2026 (currently planned) | B28: Macan BEV | C28: =(C25-C14)/(1+C19) -> 567342.83 | D28: =(D25-D14)/(1+D19) -> 928338.59 | E28: =(E25-E14)/(1+E19) -> 297802.54 | F28: =(F25-F14)/(1+F19) -> 727459.15 | G28: =(G25-G14)/(1+G19) -> 124047.74 | H28: =(H25-H14)/(1+H19) -> 24364.197 | I28: =(I25-I14)/(1+I19) -> 125961.43 | J28: =J25-J14 -> 611858.75 | K28: =(K25-K14)/(1+C19) -> 503677.79 | L28: =(L25-L14)/(1+D19) -> -5817.5866 | M28: =(M25-M14)/(1+E19) -> 574137.62 | N28: =(N25-N14)/(1+F19) -> -46457.642 | O28: =(O25-O14)/(1+G19) -> 291649.63 | P28: =P25-P14 -> 288908.16 | Q28: =(Q25-Q14)/(1+G19) -> -74604.558 | R28: =(R25-R14)/(1+H19) -> -20963.118 | S28: =(S25-S14)/(1+I19) -> 2426199.2 | T28: =SUM(SUM(C28:S28)) -> 7343904.7 | U28: =#REF!-#REF! -> #REF! | V28: =#REF!-#REF! -> #REF! | W28: =SUM(C28:S28) -> 7343904.7
B29: Cayenne E3 II | C29: =(C26-C15)/(1+C19) -> 216715.09 | D29: =(D26-D15)/(1+D19) -> 274260.99 | E29: =(E26-E15)/(1+E19) -> 163989.93 | F29: =(F26-F15)/(1+F19) -> 203706.67 | G29: =(G26-G15)/(1+G19) -> 1051048.7 | H29: =(H26-H15)/(1+H19) -> 8540.0277 | I29: =(I26-I15)/(1+I19) -> -427063.13 | J29: =(J26-J15) -> 1128026.9 | K29: =(K26-K15)/(1+K19) -> 19496.623 | L29: =(L26-L15)/(1+L19) -> 44190.051 | M29: =(M26-M15)/(1+M19) -> 528230.89 | N29: =(N26-N15)/(1+N19) -> -75657.103 | O29: =(O26-O15)/(1+O19) -> 592198.68 | P29: =(P26-P15) -> 507942.17 | Q29: =(Q26-Q15)/(1+Q19) -> -10550.85 | R29: =(R26-R15)/(1+R19) -> -38999.553 | S29: =(S26-S15)/(1+S19) -> -202312.55 | T29: =SUM(SUM(C29:S29)) -> 3983763.6
B30: Cayenne E4 | C30: =(C27-C16)/(1+C19) -> 33660.214 | D30: =(D27-D16)/(1+D19) -> -35116.386 | E30: =(E27-E16)/(1+E19) -> -576075.07 | F30: =(F27-F16)/(1+F19) -> 224773.85 | G30: =(G27-G16)/(1+G19) -> 12336.184 | H30: =(H27-H16)/(1+H19) -> -67177.933 | I30: =(I27-I16)/(1+I19) -> -98894.989 | J30: =(J27-J16)/(1+J19) -> 877147.84 | ... O30: =(O27-O16)/(1+O19) -> -247424.73 | P30: =(P27-P16) -> -661095.4 | Q30: 0 | R30: =(R27-R16)/(1+R19) -> -46324.576 | S30: =(S27-S16)/(1+S19) -> 299294.41 | T30: =SUM(SUM(C30:S30)) -> 231026.83
B31: Total | C31: =SUM(C28:C30) -> 817718.13 | D31: =SUM(D28:D30) -> 1167483.2 | E31: =SUM(E28:E30) -> -114282.61 | F31: =SUM(F28:F30) -> 1155939.7 | G31: =SUM(G28:G30) -> 1187432.6 | H31: =SUM(H28:H30) -> -34273.708 | I31: =SUM(I28:I30) -> -399996.69 | J31: =SUM(J28:J30) -> 2617033.5 | ... S31: =SUM(S28:S30) -> 2523181.1 | T31: =SUM(SUM(C31:S31)) -> 11558695
A32: Efficiency Recommendation (CPL und L2S-Rate)
A33: Sales Gap Recommendation | J33: Macan, E4 | K33: Macan, E4 | L33: Macan, E4 | M33: Macan, E4
C35: PCGB | D35: PD | E35: PKO | F35: POF | G35: PIT | H35: TRK | I35: PCL | J35: PIB SPA | K35: PNO | L35: PIB POR | M35: PCH | N35: PTW | O35: PCA | P35: PPL | Q35: PJ | R35: PBR | S35: PCNA | T35: TOTAL | U35: TOTAL without PJ, PBR, PCNA
A36: Scenario 1 (Cover budget gaps) | B36: Macan BEV | C36: 100000 | D36: 150000 | E36: 50000 | F36: 150000 | G36: 50000 | H36: 10000 | I36: 50000 | J36: 50000 | K36: 40000 | L36: 30000 | M36: 40000 | N36: 10000 | O36: 30000 | P36: 10000 | Q36: 20000 | R36: 25000 | S36: 200000 | T36: =SUM(C36:S36) -> 1015000 | U36: =SUM(D36:T36) -> 1930000
B37: Cayenne E3 II | C37: 50000 | D37: 50000 | E37: 30000 | F37: 50000 | G37: 160000 | H37: 10000 | I37: 20000 | J37: 0 | K37: 0 | L37: 0 | M37: 0 | N37: 30000 | O37: 60000 | P37: 30000 | Q37: 20000 | R37: 25000 | S37: 50000 | T37: =SUM(C37:S37) -> 585000 | U37: =SUM(D37:T37) -> 1120000
B38: Cayenne E4 | C38: 130000 | D38: 100000 | E38: 20000 | F38: 100000 | G38: 90000 | H38: 40000 | I38: 30000 | J38: 100000 | K38: 60000 | L38: 30000 | M38: 20000 | N38: 20000 | O38: 10000 | P38: 20000 | Q38: 20000 | R38: 10000 | S38: 0 | T38: =SUM(C38:S38) -> 800000 | U38: =SUM(D38:T38) -> 1470000
B39: Total | C39: =SUM(C36:C38) -> 280000 | D39: =SUM(D36:D38) -> 300000 | E39: =SUM(E36:E38) -> 100000 | F39: =SUM(F36:F38) -> 300000 | G39: =SUM(G36:G38) -> 300000 | H39: =SUM(H36:H38) -> 60000 | I39: =SUM(I36:I38) -> 100000 | J39: =SUM(J36:J38) -> 150000 | ... S39: =SUM(S36:S38) -> 250000 | T39: =SUM(C39:S39) -> 2400000 | U39: =SUM(D39:T39) -> 4520000
A40: Scenario 2 (Efficiency Co Pilot) | B40: Macan BEV | C40: 73000 | D40: 43000 | E40: 79000 | F40: 25000 | G40: 74000 | H40: 204000 | I40: 23000 | J40: 0 | K40: 0 | L40: 94000 | M40: 0 | N40: 0 | O40: 0 | P40: 0 | Q40: 0 | R40: 74000 | S40: 31000 | T40: 720000 | U40: 720000
B41: Cayenne E3 II | C41: 92000 | D41: 80000 | E41: 79000 | F41: 25000 | G41: 23000 | H41: 209000 | I41: 74000 | J41: 0 | K41: 0 | L41: 94000 | M41: 0 | N41: 0 | O41: 0 | P41: 0 | Q41: 0 | R41: 37000 | S41: 92000 | T41: 805000 | U41: 805000
...

Sheet Media Mix
A1: Close the gap 2026 | C1: PCGB | D1: PCGB | E1: PD | F1: PD | G1: PKO | H1: PKO | I1: POF | J1: POF | K1: PIT | L1: PIT | M1: TRK | N1: TRK | O1: PCL | P1: PCL | Q1: PIB SPA | R1: PIB SPA | S1: PNO | T1: PNO | U1: PIB POR | V1: PIB POR | W1: PCH | X1: PCH | Y1: PTW | Z1: PTW | AA1: PCA | AB1: PCA | AC1: PPL | AD1: PPL
C2: Start | D2: Ende | E2: Start | F2: Ende | G2: Start | H2: Ende | I2: Start | J2: Ende | K2: Start | L2: Ende | M2: Start | N2: Ende | O2: Start | P2: Ende | Q2: Start | R2: Ende | S2: Start | T2: Ende | U2: Start | V2: Ende | W2: Start | X2: Ende | Y2: Start | Z2: Ende | AA2: Start | AB2: Ende | AC2: Start | AD2: Ende
A3: Macan BEV | B3: Google Ads | C3: 46143 | D3: 46264 | E3: 46143 | F3: 46264 | G3: 46143 | H3: 46264 | I3: 46143 | J3: 46264 | K3: 46143 | L3: 46264 | M3: 46143 | N3: 46264 | O3: 46143 | P3: 46264 | Q3: 46143 | R3: 46264 | S3: 46143 | T3: 46264 | U3: 46143 | V3: 46264 | W3: 46143 | X3: 46264 | Y3: 46143 | Z3: 46264 | AA3: 46143 | AB3: 46264 | AC3: 46143 | AD3: 46264
A4: Macan BEV | B4: Google Inventory Ads | C4: 46143 | D4: 46264 | G4: 46143 | H4: 46264 | I4: 46143 | J4: 46264 | K4: 46174 | L4: 46264 | O4: 46143 | P4: 46264 | Q4: 46143 | R4: 46264
A5: Macan BEV | B5: META Inventory Ads | C5: 46143 | D5: 46264 | E5: 46143 | F5: 46264 | G5: 46143 | H5: 46264 | I5: 46143 | J5: 46264 | K5: 46143 | L5: 46264 | M5: 46143 | N5: 46264 | O5: 46143 | P5: 46264 | Q5: 46143 | R5: 46264 | S5: 46143 | T5: 46264 | U5: 46143 | V5: 46264 | W5: 46143 | X5: 46264 | Y5: 46143 | Z5: 46264 | AA5: 46143 | AB5: 46264 | AC5: 46143 | AD5: 46264
A6: Macan BEV | B6: Paid Social | C6: 46204 | D6: 46264 | E6: 46204 | F6: 46264 | G6: 46204 | H6: 46264 | I6: 46204 | J6: 46264 | K6: 46204 | L6: 46264 | M6: 46204 | N6: 46264 | O6: 46204 | P6: 46264 | Q6: 46204 | R6: 46264 | S6: 46204 | T6: 46264 | U6: 46204 | V6: 46264 | W6: 46204 | X6: 46264 | Y6: 46204 | Z6: 46264 | AA6: 46204 | AB6: 46264 | AC6: 46204 | AD6: 46264
A7: Cayenne E3 II | B7: Google Ads | C7: 46143 | D7: 46264 | E7: 46143 | F7: 46264 | G7: 46143 | H7: 46264 | I7: 46143 | J7: 46264 | K7: 46143 | L7: 46264 | M7: 46174 | N7: 46264 | O7: 46143 | P7: 46264 | Y7: 46143 | Z7: 46264 | AA7: 46174 | AB7: 46264 | AC7: 46174 | AD7: 46264
A8: Cayenne E3 II | B8: Google Inventory Ads | C8: 46143 | D8: 46264 | G8: 46143 | H8: 46264 | I8: 46143 | J8: 46264 | K8: 46174 | L8: 46264 | O8: 46143 | P8: 46264 | Y8: 46143 | Z8: 46264
A9: Cayenne E3 II | B9: META Inventory Ads | C9: 46143 | D9: 46264 | E9: 46143 | F9: 46264 | G9: 46143 | H9: 46264 | I9: 46143 | J9: 46264 | K9: 46143 | L9: 46264 | M9: 46143 | N9: 46264 | O9: 46143 | P9: 46264 | Y9: 46143 | Z9: 46264 | AA9: 46143 | AB9: 46264 | AC9: 46143 | AD9: 46264
A10: Cayenne E3 II | B10: Paid Social | C10: 46204 | D10: 46264 | E10: 46204 | F10: 46264 | G10: 46204 | H10: 46264 | K10: 46204 | L10: 46264 | M10: 46204 | N10: 46264 | O10: 46204 | P10: 46264 | Y10: 46204 | Z10: 46264 | AA10: 46204 | AB10: 46264 | AC10: 46204 | AD10: 46264
A11: Cayenne E4 | B11: Google Ads | C11: 46143 | D11: 46264 | E11: 46143 | F11: 46264 | G11: 46143 | H11: 46264 | I11: 46143 | J11: 46264 | K11: 46143 | L11: 46264 | M11: 46143 | N11: 46264 | O11: 46143 | P11: 46264 | Q11: 46143 | R11: 46264 | S11: 46143 | T11: 46264 | U11: 46143 | V11: 46264 | W11: 46143 | X11: 46264 | Y11: 46143 | Z11: 46264 | AA11: 46143 | AB11: 46264 | AC11: 46143 | AD11: 46264
A12: Cayenne E4 | B12: Google Inventory Ads | C12: 46204 | D12: 46264 | G12: 46204 | H12: 46264 | I12: 46204 | J12: 46264 | K12: 46204 | L12: 46264 | O12: 46204 | P12: 46264 | Q12: 46204 | R12: 46264
A13: Cayenne E4 | B13: META Inventory Ads | C13: 46204 | D13: 46264 | E13: 46204 | F13: 46264 | G13: 46204 | H13: 46264 | I13: 46204 | J13: 46264 | K13: 46204 | L13: 46264 | M13: 46204 | N13: 46264 | O13: 46204 | P13: 46264 | Q13: 46204 | R13: 46264 | S13: 46204 | T13: 46264 | U13: 46204 | V13: 46264 | W13: 46204 | X13: 46264 | Y13: 46204 | Z13: 46264 | AA13: 46204 | AB13: 46264 | AC13: 46204 | AD13: 46264
A14: Cayenne E4 | B14: Paid Social | C14: 46204 | D14: 46264 | E14: 46204 | F14: 46264 | G14: 46204 | H14: 46264 | I14: 46204 | J14: 46264 | K14: 46204 | L14: 46264 | M14: 46204 | N14: 46264 | O14: 46204 | P14: 46264 | Q14: 46204 | R14: 46264 | S14: 46204 | T14: 46264 | U14: 46204 | V14: 46264 | W14: 46204 | X14: 46264 | Y14: 46204 | Z14: 46264 | AA14: 46204 | AB14: 46264 | AC14: 46204 | AD14: 46264

Sheet Zeitstrahl nach Markt
A1: 📅 Zeitstrahl (Wochenansicht) – Measuren je Markt
A2: Legende (Baureihen): | B2: Macan BEV | C2: Cayenne E3 II | D2: Cayenne E4
E3: 46139 | F3: 46146 | G3: 46153 | H3: 46160 | I3: 46167 | J3: 46174 | K3: 46181 | L3: 46188 | M3: 46195 | N3: 46202 | O3: 46209 | P3: 46216 | Q3: 46223 | R3: 46230 | S3: 46237 | T3: 46244 | U3: 46251 | V3: 46258 | AB3: 46139 | AC3: 46146 | AD3: 46153 | AE3: 46160 | AF3: 46167 | AG3: 46174 | AH3: 46181 | AI3: 46188 | AJ3: 46195 | AK3: 46202 | AL3: 46209 | AM3: 46216 | AN3: 46223 | AO3: 46230 | AP3: 46237 | AQ3: 46244 | AR3: 46251 | AS3: 46258
A4: Markt: PCGB | X4: Markt: PCGB (Survey)
A5: Model | B5: CTG Measure | C5: Start | D5: Ende | E5: CW18 | F5: CW19 | G5: CW20 | H5: CW21 | I5: CW22 | J5: CW23 | K5: CW24 | L5: CW25 | M5: CW26 | N5: CW27 | O5: CW28 | P5: CW29 | Q5: CW30 | R5: CW31 | S5: CW32 | T5: CW33 | U5: CW34 | V5: CW35 | X5: Model | Y5: Local Measure | Z5: Start | AA5: Ende | AB5: CW18 | AC5: CW19 | AD5: CW20 | AE5: CW21 | AF5: CW22 | AG5: CW23 | AH5: CW24 | AI5: CW25 | AJ5: CW26 | AK5: CW27 | AL5: CW28 | AM5: CW29 | AN5: CW30 | AO5: CW31 | AP5: CW32 | AQ5: CW33 | AR5: CW34 | AS5: CW35 | AT5: Channel | AU5: Budget | AV5: KPI | AW5: Audience
A6: Macan BEV | B6: Google Ads | C6: 46143 | D6: 46264 | E6: =IFERROR(IF(OR($A6="",$A6="Model",LEFT($A6,5)="Markt"),"",IF(AND($C6<=E$3+6,$D6>=E$3),"■","")),"") -> ■ | F6: =IFERROR(IF(OR($A6="",$A6="Model",LEFT($A6,5)="Markt"),"",IF(AND($C6<=F$3+6,$D6>=F$3),"■","")),"") -> ■ | G6: =IFERROR(IF(OR($A6="",$A6="Model",LEFT($A6,5)="Markt"),"",IF(AND($C6<=G$3+6,$D6>=G$3),"■","")),"") -> ■ | H6: =IFERROR(IF(OR($A6="",$A6="Model",LEFT($A6,5)="Markt"),"",IF(AND($C6<=H$3+6,$D6>=H$3),"■","")),"") -> ■ | I6: =IFERROR(IF(OR($A6="",$A6="Model",LEFT($A6,5)="Markt"),"",IF(AND($C6<=I$3+6,$D6>=I$3),"■","")),"") -> ■ | J6: =IFERROR(IF(OR($A6="",$A6="Model",LEFT($A6,5)="Markt"),"",IF(AND($C6<=J$3+6,$D6>=J$3),"■","")),"") -> ■ | K6: =IFERROR(IF(OR($A6="",$A6="Model",LEFT($A6,5)="Markt"),"",IF(AND($C6<=K$3+6,$D6>=K$3),"■","")),"") -> ■ | L6: =IFERROR(IF(OR($A6="",$A6="Model",LEFT($A6,5)="Markt"),"",IF(AND($C6<=L$3+6,$D6>=L$3),"■","")),"") -> ■ | ... V6: =IFERROR(IF(OR($A6="",$A6="Model",LEFT($A6,5)="Markt"),"",IF(AND($C6<=V$3+6,$D6>=V$3),"■","")),"") -> ■ | X6: Cayenne E3 II | Y6: Always on | AB6: =IF(AND($Z6<=AB$3+6,$AA6>=AB$3),"■","") | AC6: =IF(AND($Z6<=AC$3+6,$AA6>=AC$3),"■","") | AD6: =IF(AND($Z6<=AD$3+6,$AA6>=AD$3),"■","") | AE6: =IF(AND($Z6<=AE$3+6,$AA6>=AE$3),"■","") | AF6: =IF(AND($Z6<=AF$3+6,$AA6>=AF$3),"■","") | AG6: =IF(AND($Z6<=AG$3+6,$AA6>=AG$3),"■","") | AH6: =IF(AND($Z6<=AH$3+6,$AA6>=AH$3),"■","") | AI6: =IF(AND($Z6<=AI$3+6,$AA6>=AI$3),"■","") | ... AS6: =IF(AND($Z6<=AS$3+6,$AA6>=AS$3),"■","")
A7: Macan BEV | B7: Google Inventory Ads | C7: 46143 | D7: 46264 | E7: =IFERROR(IF(OR($A7="",$A7="Model",LEFT($A7,5)="Markt"),"",IF(AND($C7<=E$3+6,$D7>=E$3),"■","")),"") -> ■ | F7: =IFERROR(IF(OR($A7="",$A7="Model",LEFT($A7,5)="Markt"),"",IF(AND($C7<=F$3+6,$D7>=F$3),"■","")),"") -> ■ | G7: =IFERROR(IF(OR($A7="",$A7="Model",LEFT($A7,5)="Markt"),"",IF(AND($C7<=G$3+6,$D7>=G$3),"■","")),"") -> ■ | H7: =IFERROR(IF(OR($A7="",$A7="Model",LEFT($A7,5)="Markt"),"",IF(AND($C7<=H$3+6,$D7>=H$3),"■","")),"") -> ■ | I7: =IFERROR(IF(OR($A7="",$A7="Model",LEFT($A7,5)="Markt"),"",IF(AND($C7<=I$3+6,$D7>=I$3),"■","")),"") -> ■ | J7: =IFERROR(IF(OR($A7="",$A7="Model",LEFT($A7,5)="Markt"),"",IF(AND($C7<=J$3+6,$D7>=J$3),"■","")),"") -> ■ | K7: =IFERROR(IF(OR($A7="",$A7="Model",LEFT($A7,5)="Markt"),"",IF(AND($C7<=K$3+6,$D7>=K$3),"■","")),"") -> ■ | L7: =IFERROR(IF(OR($A7="",$A7="Model",LEFT($A7,5)="Markt"),"",IF(AND($C7<=L$3+6,$D7>=L$3),"■","")),"") -> ■ | ... V7: =IFERROR(IF(OR($A7="",$A7="Model",LEFT($A7,5)="Markt"),"",IF(AND($C7<=V$3+6,$D7>=V$3),"■","")),"") -> ■
A8: Macan BEV | B8: META Inventory Ads | C8: 46143 | D8: 46264 | E8: =IFERROR(IF(OR($A8="",$A8="Model",LEFT($A8,5)="Markt"),"",IF(AND($C8<=E$3+6,$D8>=E$3),"■","")),"") -> ■ | F8: =IFERROR(IF(OR($A8="",$A8="Model",LEFT($A8,5)="Markt"),"",IF(AND($C8<=F$3+6,$D8>=F$3),"■","")),"") -> ■ | G8: =IFERROR(IF(OR($A8="",$A8="Model",LEFT($A8,5)="Markt"),"",IF(AND($C8<=G$3+6,$D8>=G$3),"■","")),"") -> ■ | H8: =IFERROR(IF(OR($A8="",$A8="Model",LEFT($A8,5)="Markt"),"",IF(AND($C8<=H$3+6,$D8>=H$3),"■","")),"") -> ■ | I8: =IFERROR(IF(OR($A8="",$A8="Model",LEFT($A8,5)="Markt"),"",IF(AND($C8<=I$3+6,$D8>=I$3),"■","")),"") -> ■ | J8: =IFERROR(IF(OR($A8="",$A8="Model",LEFT($A8,5)="Markt"),"",IF(AND($C8<=J$3+6,$D8>=J$3),"■","")),"") -> ■ | K8: =IFERROR(IF(OR($A8="",$A8="Model",LEFT($A8,5)="Markt"),"",IF(AND($C8<=K$3+6,$D8>=K$3),"■","")),"") -> ■ | L8: =IFERROR(IF(OR($A8="",$A8="Model",LEFT($A8,5)="Markt"),"",IF(AND($C8<=L$3+6,$D8>=L$3),"■","")),"") -> ■ | ... V8: =IFERROR(IF(OR($A8="",$A8="Model",LEFT($A8,5)="Markt"),"",IF(AND($C8<=V$3+6,$D8>=V$3),"■","")),"") -> ■
A9: Macan BEV | B9: Paid Social | C9: 46204 | D9: 46264 | E9: =IFERROR(IF(OR($A9="",$A9="Model",LEFT($A9,5)="Markt"),"",IF(AND($C9<=E$3+6,$D9>=E$3),"■","")),"") | F9: =IFERROR(IF(OR($A9="",$A9="Model",LEFT($A9,5)="Markt"),"",IF(AND($C9<=F$3+6,$D9>=F$3),"■","")),"") | G9: =IFERROR(IF(OR($A9="",$A9="Model",LEFT($A9,5)="Markt"),"",IF(AND($C9<=G$3+6,$D9>=G$3),"■","")),"") | H9: =IFERROR(IF(OR($A9="",$A9="Model",LEFT($A9,5)="Markt"),"",IF(AND($C9<=H$3+6,$D9>=H$3),"■","")),"") | I9: =IFERROR(IF(OR($A9="",$A9="Model",LEFT($A9,5)="Markt"),"",IF(AND($C9<=I$3+6,$D9>=I$3),"■","")),"") | J9: =IFERROR(IF(OR($A9="",$A9="Model",LEFT($A9,5)="Markt"),"",IF(AND($C9<=J$3+6,$D9>=J$3),"■","")),"") | K9: =IFERROR(IF(OR($A9="",$A9="Model",LEFT($A9,5)="Markt"),"",IF(AND($C9<=K$3+6,$D9>=K$3),"■","")),"") | L9: =IFERROR(IF(OR($A9="",$A9="Model",LEFT($A9,5)="Markt"),"",IF(AND($C9<=L$3+6,$D9>=L$3),"■","")),"") | ... V9: =IFERROR(IF(OR($A9="",$A9="Model",LEFT($A9,5)="Markt"),"",IF(AND($C9<=V$3+6,$D9>=V$3),"■","")),"") -> ■
A10: Cayenne E3 II | B10: Google Ads | C10: 46143 | D10: 46264 | E10: =IFERROR(IF(OR($A10="",$A10="Model",LEFT($A10,5)="Markt"),"",IF(AND($C10<=E$3+6,$D10>=E$3),"■","")),"") -> ■ | F10: =IFERROR(IF(OR($A10="",$A10="Model",LEFT($A10,5)="Markt"),"",IF(AND($C10<=F$3+6,$D10>=F$3),"■","")),"") -> ■ | G10: =IFERROR(IF(OR($A10="",$A10="Model",LEFT($A10,5)="Markt"),"",IF(AND($C10<=G$3+6,$D10>=G$3),"■","")),"") -> ■ | H10: =IFERROR(IF(OR($A10="",$A10="Model",LEFT($A10,5)="Markt"),"",IF(AND($C10<=H$3+6,$D10>=H$3),"■","")),"") -> ■ | I10: =IFERROR(IF(OR($A10="",$A10="Model",LEFT($A10,5)="Markt"),"",IF(AND($C10<=I$3+6,$D10>=I$3),"■","")),"") -> ■ | J10: =IFERROR(IF(OR($A10="",$A10="Model",LEFT($A10,5)="Markt"),"",IF(AND($C10<=J$3+6,$D10>=J$3),"■","")),"") -> ■ | K10: =IFERROR(IF(OR($A10="",$A10="Model",LEFT($A10,5)="Markt"),"",IF(AND($C10<=K$3+6,$D10>=K$3),"■","")),"") -> ■ | L10: =IFERROR(IF(OR($A10="",$A10="Model",LEFT($A10,5)="Markt"),"",IF(AND($C10<=L$3+6,$D10>=L$3),"■","")),"") -> ■ | ... V10: =IFERROR(IF(OR($A10="",$A10="Model",LEFT($A10,5)="Markt"),"",IF(AND($C10<=V$3+6,$D10>=V$3),"■","")),"") -> ■
A11: Cayenne E3 II | B11: Google Inventory Ads | C11: 46143 | D11: 46264 | E11: =IFERROR(IF(OR($A11="",$A11="Model",LEFT($A11,5)="Markt"),"",IF(AND($C11<=E$3+6,$D11>=E$3),"■","")),"") -> ■ | F11: =IFERROR(IF(OR($A11="",$A11="Model",LEFT($A11,5)="Markt"),"",IF(AND($C11<=F$3+6,$D11>=F$3),"■","")),"") -> ■ | G11: =IFERROR(IF(OR($A11="",$A11="Model",LEFT($A11,5)="Markt"),"",IF(AND($C11<=G$3+6,$D11>=G$3),"■","")),"") -> ■ | H11: =IFERROR(IF(OR($A11="",$A11="Model",LEFT($A11,5)="Markt"),"",IF(AND($C11<=H$3+6,$D11>=H$3),"■","")),"") -> ■ | I11: =IFERROR(IF(OR($A11="",$A11="Model",LEFT($A11,5)="Markt"),"",IF(AND($C11<=I$3+6,$D11>=I$3),"■","")),"") -> ■ | J11: =IFERROR(IF(OR($A11="",$A11="Model",LEFT($A11,5)="Markt"),"",IF(AND($C11<=J$3+6,$D11>=J$3),"■","")),"") -> ■ | K11: =IFERROR(IF(OR($A11="",$A11="Model",LEFT($A11,5)="Markt"),"",IF(AND($C11<=K$3+6,$D11>=K$3),"■","")),"") -> ■ | L11: =IFERROR(IF(OR($A11="",$A11="Model",LEFT($A11,5)="Markt"),"",IF(AND($C11<=L$3+6,$D11>=L$3),"■","")),"") -> ■ | ... V11: =IFERROR(IF(OR($A11="",$A11="Model",LEFT($A11,5)="Markt"),"",IF(AND($C11<=V$3+6,$D11>=V$3),"■","")),"") -> ■
A12: Cayenne E3 II | B12: META Inventory Ads | C12: 46143 | D12: 46264 | E12: =IFERROR(IF(OR($A12="",$A12="Model",LEFT($A12,5)="Markt"),"",IF(AND($C12<=E$3+6,$D12>=E$3),"■","")),"") -> ■ | F12: =IFERROR(IF(OR($A12="",$A12="Model",LEFT($A12,5)="Markt"),"",IF(AND($C12<=F$3+6,$D12>=F$3),"■","")),"") -> ■ | G12: =IFERROR(IF(OR($A12="",$A12="Model",LEFT($A12,5)="Markt"),"",IF(AND($C12<=G$3+6,$D12>=G$3),"■","")),"") -> ■ | H12: =IFERROR(IF(OR($A12="",$A12="Model",LEFT($A12,5)="Markt"),"",IF(AND($C12<=H$3+6,$D12>=H$3),"■","")),"") -> ■ | I12: =IFERROR(IF(OR($A12="",$A12="Model",LEFT($A12,5)="Markt"),"",IF(AND($C12<=I$3+6,$D12>=I$3),"■","")),"") -> ■ | J12: =IFERROR(IF(OR($A12="",$A12="Model",LEFT($A12,5)="Markt"),"",IF(AND($C12<=J$3+6,$D12>=J$3),"■","")),"") -> ■ | K12: =IFERROR(IF(OR($A12="",$A12="Model",LEFT($A12,5)="Markt"),"",IF(AND($C12<=K$3+6,$D12>=K$3),"■","")),"") -> ■ | L12: =IFERROR(IF(OR($A12="",$A12="Model",LEFT($A12,5)="Markt"),"",IF(AND($C12<=L$3+6,$D12>=L$3),"■","")),"") -> ■ | ... V12: =IFERROR(IF(OR($A12="",$A12="Model",LEFT($A12,5)="Markt"),"",IF(AND($C12<=V$3+6,$D12>=V$3),"■","")),"") -> ■
A13: Cayenne E3 II | B13: Paid Social | C13: 46204 | D13: 46264 | E13: =IFERROR(IF(OR($A13="",$A13="Model",LEFT($A13,5)="Markt"),"",IF(AND($C13<=E$3+6,$D13>=E$3),"■","")),"") | F13: =IFERROR(IF(OR($A13="",$A13="Model",LEFT($A13,5)="Markt"),"",IF(AND($C13<=F$3+6,$D13>=F$3),"■","")),"") | G13: =IFERROR(IF(OR($A13="",$A13="Model",LEFT($A13,5)="Markt"),"",IF(AND($C13<=G$3+6,$D13>=G$3),"■","")),"") | H13: =IFERROR(IF(OR($A13="",$A13="Model",LEFT($A13,5)="Markt"),"",IF(AND($C13<=H$3+6,$D13>=H$3),"■","")),"") | I13: =IFERROR(IF(OR($A13="",$A13="Model",LEFT($A13,5)="Markt"),"",IF(AND($C13<=I$3+6,$D13>=I$3),"■","")),"") | J13: =IFERROR(IF(OR($A13="",$A13="Model",LEFT($A13,5)="Markt"),"",IF(AND($C13<=J$3+6,$D13>=J$3),"■","")),"") | K13: =IFERROR(IF(OR($A13="",$A13="Model",LEFT($A13,5)="Markt"),"",IF(AND($C13<=K$3+6,$D13>=K$3),"■","")),"") | L13: =IFERROR(IF(OR($A13="",$A13="Model",LEFT($A13,5)="Markt"),"",IF(AND($C13<=L$3+6,$D13>=L$3),"■","")),"") | ... V13: =IFERROR(IF(OR($A13="",$A13="Model",LEFT($A13,5)="Markt"),"",IF(AND($C13<=V$3+6,$D13>=V$3),"■","")),"") -> ■
A14: Cayenne E4 | B14: Google Ads | C14: 46143 | D14: 46264 | E14: =IFERROR(IF(OR($A14="",$A14="Model",LEFT($A14,5)="Markt"),"",IF(AND($C14<=E$3+6,$D14>=E$3),"■","")),"") -> ■ | F14: =IFERROR(IF(OR($A14="",$A14="Model",LEFT($A14,5)="Markt"),"",IF(AND($C14<=F$3+6,$D14>=F$3),"■","")),"") -> ■ | G14: =IFERROR(IF(OR($A14="",$A14="Model",LEFT($A14,5)="Markt"),"",IF(AND($C14<=G$3+6,$D14>=G$3),"■","")),"") -> ■ | H14: =IFERROR(IF(OR($A14="",$A14="Model",LEFT($A14,5)="Markt"),"",IF(AND($C14<=H$3+6,$D14>=H$3),"■","")),"") -> ■ | I14: =IFERROR(IF(OR($A14="",$A14="Model",LEFT($A14,5)="Markt"),"",IF(AND($C14<=I$3+6,$D14>=I$3),"■","")),"") -> ■ | J14: =IFERROR(IF(OR($A14="",$A14="Model",LEFT($A14,5)="Markt"),"",IF(AND($C14<=J$3+6,$D14>=J$3),"■","")),"") -> ■ | K14: =IFERROR(IF(OR($A14="",$A14="Model",LEFT($A14,5)="Markt"),"",IF(AND($C14<=K$3+6,$D14>=K$3),"■","")),"") -> ■ | L14: =IFERROR(IF(OR($A14="",$A14="Model",LEFT($A14,5)="Markt"),"",IF(AND($C14<=L$3+6,$D14>=L$3),"■","")),"") -> ■ | ... V14: =IFERROR(IF(OR($A14="",$A14="Model",LEFT($A14,5)="Markt"),"",IF(AND($C14<=V$3+6,$D14>=V$3),"■","")),"") -> ■
A15: Cayenne E4 | B15: Google Inventory Ads | C15: 46204 | D15: 46264 | E15: =IFERROR(IF(OR($A15="",$A15="Model",LEFT($A15,5)="Markt"),"",IF(AND($C15<=E$3+6,$D15>=E$3),"■","")),"") | F15: =IFERROR(IF(OR($A15="",$A15="Model",LEFT($A15,5)="Markt"),"",IF(AND($C15<=F$3+6,$D15>=F$3),"■","")),"") | G15: =IFERROR(IF(OR($A15="",$A15="Model",LEFT($A15,5)="Markt"),"",IF(AND($C15<=G$3+6,$D15>=G$3),"■","")),"") | H15: =IFERROR(IF(OR($A15="",$A15="Model",LEFT($A15,5)="Markt"),"",IF(AND($C15<=H$3+6,$D15>=H$3),"■","")),"") | I15: =IFERROR(IF(OR($A15="",$A15="Model",LEFT($A15,5)="Markt"),"",IF(AND($C15<=I$3+6,$D15>=I$3),"■","")),"") | J15: =IFERROR(IF(OR($A15="",$A15="Model",LEFT($A15,5)="Markt"),"",IF(AND($C15<=J$3+6,$D15>=J$3),"■","")),"") | K15: =IFERROR(IF(OR($A15="",$A15="Model",LEFT($A15,5)="Markt"),"",IF(AND($C15<=K$3+6,$D15>=K$3),"■","")),"") | L15: =IFERROR(IF(OR($A15="",$A15="Model",LEFT($A15,5)="Markt"),"",IF(AND($C15<=L$3+6,$D15>=L$3),"■","")),"") | ... V15: =IFERROR(IF(OR($A15="",$A15="Model",LEFT($A15,5)="Markt"),"",IF(AND($C15<=V$3+6,$D15>=V$3),"■","")),"") -> ■
A16: Cayenne E4 | B16: META Inventory Ads | C16: 46204 | D16: 46264 | E16: =IFERROR(IF(OR($A16="",$A16="Model",LEFT($A16,5)="Markt"),"",IF(AND($C16<=E$3+6,$D16>=E$3),"■","")),"") | F16: =IFERROR(IF(OR($A16="",$A16="Model",LEFT($A16,5)="Markt"),"",IF(AND($C16<=F$3+6,$D16>=F$3),"■","")),"") | G16: =IFERROR(IF(OR($A16="",$A16="Model",LEFT($A16,5)="Markt"),"",IF(AND($C16<=G$3+6,$D16>=G$3),"■","")),"") | H16: =IFERROR(IF(OR($A16="",$A16="Model",LEFT($A16,5)="Markt"),"",IF(AND($C16<=H$3+6,$D16>=H$3),"■","")),"") | I16: =IFERROR(IF(OR($A16="",$A16="Model",LEFT($A16,5)="Markt"),"",IF(AND($C16<=I$3+6,$D16>=I$3),"■","")),"") | J16: =IFERROR(IF(OR($A16="",$A16="Model",LEFT($A16,5)="Markt"),"",IF(AND($C16<=J$3+6,$D16>=J$3),"■","")),"") | K16: =IFERROR(IF(OR($A16="",$A16="Model",LEFT($A16,5)="Markt"),"",IF(AND($C16<=K$3+6,$D16>=K$3),"■","")),"") | L16: =IFERROR(IF(OR($A16="",$A16="Model",LEFT($A16,5)="Markt"),"",IF(AND($C16<=L$3+6,$D16>=L$3),"■","")),"") | ... V16: =IFERROR(IF(OR($A16="",$A16="Model",LEFT($A16,5)="Markt"),"",IF(AND($C16<=V$3+6,$D16>=V$3),"■","")),"") -> ■
A17: Cayenne E4 | B17: Paid Social | C17: 46204 | D17: 46264 | E17: =IFERROR(IF(OR($A17="",$A17="Model",LEFT($A17,5)="Markt"),"",IF(AND($C17<=E$3+6,$D17>=E$3),"■","")),"") | F17: =IFERROR(IF(OR($A17="",$A17="Model",LEFT($A17,5)="Markt"),"",IF(AND($C17<=F$3+6,$D17>=F$3),"■","")),"") | G17: =IFERROR(IF(OR($A17="",$A17="Model",LEFT($A17,5)="Markt"),"",IF(AND($C17<=G$3+6,$D17>=G$3),"■","")),"") | H17: =IFERROR(IF(OR($A17="",$A17="Model",LEFT($A17,5)="Markt"),"",IF(AND($C17<=H$3+6,$D17>=H$3),"■","")),"") | I17: =IFERROR(IF(OR($A17="",$A17="Model",LEFT($A17,5)="Markt"),"",IF(AND($C17<=I$3+6,$D17>=I$3),"■","")),"") | J17: =IFERROR(IF(OR($A17="",$A17="Model",LEFT($A17,5)="Markt"),"",IF(AND($C17<=J$3+6,$D17>=J$3),"■","")),"") | K17: =IFERROR(IF(OR($A17="",$A17="Model",LEFT($A17,5)="Markt"),"",IF(AND($C17<=K$3+6,$D17>=K$3),"■","")),"") | L17: =IFERROR(IF(OR($A17="",$A17="Model",LEFT($A17,5)="Markt"),"",IF(AND($C17<=L$3+6,$D17>=L$3),"■","")),"") | ... V17: =IFERROR(IF(OR($A17="",$A17="Model",LEFT($A17,5)="Markt"),"",IF(AND($C17<=V$3+6,$D17>=V$3),"■","")),"") -> ■
A18: Markt: PD | X18: Markt: PD (Survey) | AT18: {=_xlfn.LET(_xlpm.mL,A18,_xlpm.aL,B18,_xlpm.mR,X18,_xlpm.aR,Y18,_xlpm.useR,AND(_xlpm.mR<>"",_xlpm.mR<>"Model",LEFT(_xlpm.mR,6)<>"Markt:"),_xlpm.m,IF(_xlpm.useR,_xlpm.mR,_xlpm.mL),_xlpm.a,IF(_xlpm.useR,_xlpm.aR,_xlpm.aL),_xlpm.rng,IF(_xlpm.useR,X$1:X18,A$1:A18),IF(OR(_xlpm.m="",_xlpm.m="Model",LEFT(_xlpm.m,6)="Markt:"),"",_xlfn.LET(_xlpm.mkt,LOOKUP(2,1/(LEFT(_xlpm.rng,6)="Markt:"),_xlpm.rng),_xlpm.mktNameRaw,TRIM(MID(_xlpm.mkt,FIND(":",_xlpm.mkt)+1,99)),_xlpm.mktName,TRIM(SUBSTITUTE(_xlpm.mktNameRaw,"(Survey)","")),_xlfn.XLOOKUP(_xlpm.mktName&"|"&SUBSTITUTE(_xlpm.m," ","")&"|"&_xlpm.a,tblMassnahmen[Key],tblMassnahmen[Kanal],""))))} | AU18: {=_xlfn.LET(_xlpm.mL,A18,_xlpm.aL,B18,_xlpm.mR,X18,_xlpm.aR,Y18,_xlpm.useR,AND(_xlpm.mR<>"",_xlpm.mR<>"Model",LEFT(_xlpm.mR,6)<>"Markt:"),_xlpm.m,IF(_xlpm.useR,_xlpm.mR,_xlpm.mL),_xlpm.a,IF(_xlpm.useR,_xlpm.aR,_xlpm.aL),_xlpm.rng,IF(_xlpm.useR,X$1:X18,A$1:A18),IF(OR(_xlpm.m="",_xlpm.m="Model",LEFT(_xlpm.m,6)="Markt:"),"",_xlfn.LET(_xlpm.mkt,LOOKUP(2,1/(LEFT(_xlpm.rng,6)="Markt:"),_xlpm.rng),_xlpm.mktNameRaw,TRIM(MID(_xlpm.mkt,FIND(":",_xlpm.mkt)+1,99)),_xlpm.mktName,TRIM(SUBSTITUTE(_xlpm.mktNameRaw,"(Survey)","")),_xlfn.XLOOKUP(_xlpm.mktName&"|"&SUBSTITUTE(_xlpm.m," ","")&"|"&_xlpm.a,tblMassnahmen[Key],tblMassnahmen[Budget],""))))} | AV18: {=_xlfn.LET(_xlpm.mL,A18,_xlpm.aL,B18,_xlpm.mR,X18,_xlpm.aR,Y18,_xlpm.useR,AND(_xlpm.mR<>"",_xlpm.mR<>"Model",LEFT(_xlpm.mR,6)<>"Markt:"),_xlpm.m,IF(_xlpm.useR,_xlpm.mR,_xlpm.mL),_xlpm.a,IF(_xlpm.useR,_xlpm.aR,_xlpm.aL),_xlpm.rng,IF(_xlpm.useR,X$1:X18,A$1:A18),IF(OR(_xlpm.m="",_xlpm.m="Model",LEFT(_xlpm.m,6)="Markt:"),"",_xlfn.LET(_xlpm.mkt,LOOKUP(2,1/(LEFT(_xlpm.rng,6)="Markt:"),_xlpm.rng),_xlpm.mktNameRaw,TRIM(MID(_xlpm.mkt,FIND(":",_xlpm.mkt)+1,99)),_xlpm.mktName,TRIM(SUBSTITUTE(_xlpm.mktNameRaw,"(Survey)","")),_xlfn.XLOOKUP(_xlpm.mktName&"|"&SUBSTITUTE(_xlpm.m," ","")&"|"&_xlpm.a,tblMassnahmen[Key],tblMassnahmen[KPI],""))))}
A19: Model | B19: CTG Measure | C19: Start | D19: Ende | E19: CW18 | F19: CW19 | G19: CW20 | H19: CW21 | I19: CW22 | J19: CW23 | K19: CW24 | L19: CW25 | M19: CW26 | N19: CW27 | O19: CW28 | P19: CW29 | Q19: CW30 | R19: CW31 | S19: CW32 | T19: CW33 | U19: CW34 | V19: CW35 | X19: Model | Y19: Local Measure | Z19: Start | AA19: Ende | AB19: CW18 | AC19: CW19 | AD19: CW20 | AE19: CW21 | AF19: CW22 | AG19: CW23 | AH19: CW24 | AI19: CW25 | AJ19: CW26 | AK19: CW27 | AL19: CW28 | AM19: CW29 | AN19: CW30 | AO19: CW31 | AP19: CW32 | AQ19: CW33 | AR19: CW34 | AS19: CW35 | AT19: Channel | AU19: Budget | AV19: KPI | AW19: Audience
A20: Macan BEV | B20: Google Ads | C20: 46143 | D20: 46264 | E20: =IFERROR(IF(OR($A20="",$A20="Model",LEFT($A20,5)="Markt"),"",IF(AND($C20<=E$3+6,$D20>=E$3),"■","")),"") -> ■ | F20: =IFERROR(IF(OR($A20="",$A20="Model",LEFT($A20,5)="Markt"),"",IF(AND($C20<=F$3+6,$D20>=F$3),"■","")),"") -> ■ | G20: =IFERROR(IF(OR($A20="",$A20="Model",LEFT($A20,5)="Markt"),"",IF(AND($C20<=G$3+6,$D20>=G$3),"■","")),"") -> ■ | H20: =IFERROR(IF(OR($A20="",$A20="Model",LEFT($A20,5)="Markt"),"",IF(AND($C20<=H$3+6,$D20>=H$3),"■","")),"") -> ■ | I20: =IFERROR(IF(OR($A20="",$A20="Model",LEFT($A20,5)="Markt"),"",IF(AND($C20<=I$3+6,$D20>=I$3),"■","")),"") -> ■ | J20: =IFERROR(IF(OR($A20="",$A20="Model",LEFT($A20,5)="Markt"),"",IF(AND($C20<=J$3+6,$D20>=J$3),"■","")),"") -> ■ | K20: =IFERROR(IF(OR($A20="",$A20="Model",LEFT($A20,5)="Markt"),"",IF(AND($C20<=K$3+6,$D20>=K$3),"■","")),"") -> ■ | L20: =IFERROR(IF(OR($A20="",$A20="Model",LEFT($A20,5)="Markt"),"",IF(AND($C20<=L$3+6,$D20>=L$3),"■","")),"") -> ■ | ... V20: =IFERROR(IF(OR($A20="",$A20="Model",LEFT($A20,5)="Markt"),"",IF(AND($C20<=V$3+6,$D20>=V$3),"■","")),"") -> ■ | X20: Macan H2 | Y20: 20056448_20056448_POR_RNG_RNG_DEU_T1_NU_EUR_2025-12-31_2026-12-30_LOCAL-SEANATIONAL2026 | Z20: 46026 | AA20: 46386 | AB20: =IF(AND($Z20<=(AB$3+6),$AA20>=AB$3),"■","") -> ■ | AC20: =IF(AND($Z20<=(AC$3+6),$AA20>=AC$3),"■","") -> ■ | AD20: =IF(AND($Z20<=(AD$3+6),$AA20>=AD$3),"■","") -> ■ | AE20: =IF(AND($Z20<=(AE$3+6),$AA20>=AE$3),"■","") -> ■ | AF20: =IF(AND($Z20<=(AF$3+6),$AA20>=AF$3),"■","") -> ■ | AG20: =IF(AND($Z20<=(AG$3+6),$AA20>=AG$3),"■","") -> ■ | AH20: =IF(AND($Z20<=(AH$3+6),$AA20>=AH$3),"■","") -> ■ | AI20: =IF(AND($Z20<=(AI$3+6),$AA20>=AI$3),"■","") -> ■ | ... AS20: =IF(AND($Z20<=(AS$3+6),$AA20>=AS$3),"■","") -> ■ | AT20: Search | AU20: 182500 | AV20: Dealer contact form submitted (DCFS) | AW20: Keyword Targeting / see above
A21: Macan BEV | B21: META Inventory Ads | C21: 46143 | D21: 46264 | E21: =IFERROR(IF(OR($A21="",$A21="Model",LEFT($A21,5)="Markt"),"",IF(AND($C21<=E$3+6,$D21>=E$3),"■","")),"") -> ■ | F21: =IFERROR(IF(OR($A21="",$A21="Model",LEFT($A21,5)="Markt"),"",IF(AND($C21<=F$3+6,$D21>=F$3),"■","")),"") -> ■ | G21: =IFERROR(IF(OR($A21="",$A21="Model",LEFT($A21,5)="Markt"),"",IF(AND($C21<=G$3+6,$D21>=G$3),"■","")),"") -> ■ | H21: =IFERROR(IF(OR($A21="",$A21="Model",LEFT($A21,5)="Markt"),"",IF(AND($C21<=H$3+6,$D21>=H$3),"■","")),"") -> ■ | I21: =IFERROR(IF(OR($A21="",$A21="Model",LEFT($A21,5)="Markt"),"",IF(AND($C21<=I$3+6,$D21>=I$3),"■","")),"") -> ■ | J21: =IFERROR(IF(OR($A21="",$A21="Model",LEFT($A21,5)="Markt"),"",IF(AND($C21<=J$3+6,$D21>=J$3),"■","")),"") -> ■ | K21: =IFERROR(IF(OR($A21="",$A21="Model",LEFT($A21,5)="Markt"),"",IF(AND($C21<=K$3+6,$D21>=K$3),"■","")),"") -> ■ | L21: =IFERROR(IF(OR($A21="",$A21="Model",LEFT($A21,5)="Markt"),"",IF(AND($C21<=L$3+6,$D21>=L$3),"■","")),"") -> ■ | ... V21: =IFERROR(IF(OR($A21="",$A21="Model",LEFT($A21,5)="Markt"),"",IF(AND($C21<=V$3+6,$D21>=V$3),"■","")),"") -> ■ | X21: Macan H2 | Y21: 20130912_20130912_POR_RNG_RNG_DEU_T1_NU_EUR_2026-02-22_2026-12-30_LOCAL-AOPROGRAMMATICPERFORMANCE2026 | Z21: 46075 | AA21: 46325 | AB21: =IF(AND($Z21<=(AB$3+6),$AA21>=AB$3),"■","") -> ■ | AC21: =IF(AND($Z21<=(AC$3+6),$AA21>=AC$3),"■","") -> ■ | AD21: =IF(AND($Z21<=(AD$3+6),$AA21>=AD$3),"■","") -> ■ | AE21: =IF(AND($Z21<=(AE$3+6),$AA21>=AE$3),"■","") -> ■ | AF21: =IF(AND($Z21<=(AF$3+6),$AA21>=AF$3),"■","") -> ■ | AG21: =IF(AND($Z21<=(AG$3+6),$AA21>=AG$3),"■","") -> ■ | AH21: =IF(AND($Z21<=(AH$3+6),$AA21>=AH$3),"■","") -> ■ | AI21: =IF(AND($Z21<=(AI$3+6),$AA21>=AI$3),"■","") -> ■ | ... AS21: =IF(AND($Z21<=(AS$3+6),$AA21>=AS$3),"■","") -> ■ | AT21: Programmatic | AU21: 190000 | AV21: Dealer contact form submitted (DCFS) | AW21: Complex Audience Setup including Prospecting LAL and Retargeting Audiences / see above
A22: Macan BEV | B22: Paid Social | C22: 46204 | D22: 46264 | E22: =IFERROR(IF(OR($A22="",$A22="Model",LEFT($A22,5)="Markt"),"",IF(AND($C22<=E$3+6,$D22>=E$3),"■","")),"") | F22: =IFERROR(IF(OR($A22="",$A22="Model",LEFT($A22,5)="Markt"),"",IF(AND($C22<=F$3+6,$D22>=F$3),"■","")),"") | G22: =IFERROR(IF(OR($A22="",$A22="Model",LEFT($A22,5)="Markt"),"",IF(AND($C22<=G$3+6,$D22>=G$3),"■","")),"") | H22: =IFERROR(IF(OR($A22="",$A22="Model",LEFT($A22,5)="Markt"),"",IF(AND($C22<=H$3+6,$D22>=H$3),"■","")),"") | I22: =IFERROR(IF(OR($A22="",$A22="Model",LEFT($A22,5)="Markt"),"",IF(AND($C22<=I$3+6,$D22>=I$3),"■","")),"") | J22: =IFERROR(IF(OR($A22="",$A22="Model",LEFT($A22,5)="Markt"),"",IF(AND($C22<=J$3+6,$D22>=J$3),"■","")),"") | K22: =IFERROR(IF(OR($A22="",$A22="Model",LEFT($A22,5)="Markt"),"",IF(AND($C22<=K$3+6,$D22>=K$3),"■","")),"") | L22: =IFERROR(IF(OR($A22="",$A22="Model",LEFT($A22,5)="Markt"),"",IF(AND($C22<=L$3+6,$D22>=L$3),"■","")),"") | ... V22: =IFERROR(IF(OR($A22="",$A22="Model",LEFT($A22,5)="Markt"),"",IF(AND($C22<=V$3+6,$D22>=V$3),"■","")),"") -> ■ | X22: Macan H2 | Y22: 20172604_20172604_POR_MAC_SUV_DEU_T1_NU_EUR_2026-02-20_2026-10-31_LOCAL-MACANDIENSTWAGENPUSH2026 | Z22: 46118 | AA22: 46249 | AB22: =IF(AND($Z22<=(AB$3+6),$AA22>=AB$3),"■","") -> ■ | AC22: =IF(AND($Z22<=(AC$3+6),$AA22>=AC$3),"■","") -> ■ | AD22: =IF(AND($Z22<=(AD$3+6),$AA22>=AD$3),"■","") -> ■ | AE22: =IF(AND($Z22<=(AE$3+6),$AA22>=AE$3),"■","") -> ■ | AF22: =IF(AND($Z22<=(AF$3+6),$AA22>=AF$3),"■","") -> ■ | AG22: =IF(AND($Z22<=(AG$3+6),$AA22>=AG$3),"■","") -> ■ | AH22: =IF(AND($Z22<=(AH$3+6),$AA22>=AH$3),"■","") -> ■ | AI22: =IF(AND($Z22<=(AI$3+6),$AA22>=AI$3),"■","") -> ■ | ... AS22: =IF(AND($Z22<=(AS$3+6),$AA22>=AS$3),"■","") | AT22: Social,Programmatic | AU22: 170000 | AV22: Model page visit,Dealer contact form submitted (DCFS) | AW22: Business People with high income who look for a luxury company car / Retargeting on Macan Interest like Page Visitors or Dealer Contact Starters for a Macan
A23: Cayenne E3 II | B23: Google Ads | C23: 46143 | D23: 46264 | E23: =IFERROR(IF(OR($A23="",$A23="Model",LEFT($A23,5)="Markt"),"",IF(AND($C23<=E$3+6,$D23>=E$3),"■","")),"") -> ■ | F23: =IFERROR(IF(OR($A23="",$A23="Model",LEFT($A23,5)="Markt"),"",IF(AND($C23<=F$3+6,$D23>=F$3),"■","")),"") -> ■ | G23: =IFERROR(IF(OR($A23="",$A23="Model",LEFT($A23,5)="Markt"),"",IF(AND($C23<=G$3+6,$D23>=G$3),"■","")),"") -> ■ | H23: =IFERROR(IF(OR($A23="",$A23="Model",LEFT($A23,5)="Markt"),"",IF(AND($C23<=H$3+6,$D23>=H$3),"■","")),"") -> ■ | I23: =IFERROR(IF(OR($A23="",$A23="Model",LEFT($A23,5)="Markt"),"",IF(AND($C23<=I$3+6,$D23>=I$3),"■","")),"") -> ■ | J23: =IFERROR(IF(OR($A23="",$A23="Model",LEFT($A23,5)="Markt"),"",IF(AND($C23<=J$3+6,$D23>=J$3),"■","")),"") -> ■ | K23: =IFERROR(IF(OR($A23="",$A23="Model",LEFT($A23,5)="Markt"),"",IF(AND($C23<=K$3+6,$D23>=K$3),"■","")),"") -> ■ | L23: =IFERROR(IF(OR($A23="",$A23="Model",LEFT($A23,5)="Markt"),"",IF(AND($C23<=L$3+6,$D23>=L$3),"■","")),"") -> ■ | ... V23: =IFERROR(IF(OR($A23="",$A23="Model",LEFT($A23,5)="Markt"),"",IF(AND($C23<=V$3+6,$D23>=V$3),"■","")),"") -> ■ | X23: Cayenne E3 II | Y23: 20056448_20056448_POR_RNG_RNG_DEU_T1_NU_EUR_2025-12-31_2026-12-30_LOCAL-SEANATIONAL2026 | Z23: 46026 | AA23: 46386 | AB23: =IF(AND($Z23<=(AB$3+6),$AA23>=AB$3),"■","") -> ■ | AC23: =IF(AND($Z23<=(AC$3+6),$AA23>=AC$3),"■","") -> ■ | AD23: =IF(AND($Z23<=(AD$3+6),$AA23>=AD$3),"■","") -> ■ | AE23: =IF(AND($Z23<=(AE$3+6),$AA23>=AE$3),"■","") -> ■ | AF23: =IF(AND($Z23<=(AF$3+6),$AA23>=AF$3),"■","") -> ■ | AG23: =IF(AND($Z23<=(AG$3+6),$AA23>=AG$3),"■","") -> ■ | AH23: =IF(AND($Z23<=(AH$3+6),$AA23>=AH$3),"■","") -> ■ | AI23: =IF(AND($Z23<=(AI$3+6),$AA23>=AI$3),"■","") -> ■ | ... AS23: =IF(AND($Z23<=(AS$3+6),$AA23>=AS$3),"■","") -> ■ | AT23: Search | AU23: 182500 | AV23: Dealer contact form submitted (DCFS) | AW23: Keyword Targeting / see above
A24: Cayenne E3 II | B24: META Inventory Ads | C24: 46143 | D24: 46264 | E24: =IFERROR(IF(OR($A24="",$A24="Model",LEFT($A24,5)="Markt"),"",IF(AND($C24<=E$3+6,$D24>=E$3),"■","")),"") -> ■ | F24: =IFERROR(IF(OR($A24="",$A24="Model",LEFT($A24,5)="Markt"),"",IF(AND($C24<=F$3+6,$D24>=F$3),"■","")),"") -> ■ | G24: =IFERROR(IF(OR($A24="",$A24="Model",LEFT($A24,5)="Markt"),"",IF(AND($C24<=G$3+6,$D24>=G$3),"■","")),"") -> ■ | H24: =IFERROR(IF(OR($A24="",$A24="Model",LEFT($A24,5)="Markt"),"",IF(AND($C24<=H$3+6,$D24>=H$3),"■","")),"") -> ■ | I24: =IFERROR(IF(OR($A24="",$A24="Model",LEFT($A24,5)="Markt"),"",IF(AND($C24<=I$3+6,$D24>=I$3),"■","")),"") -> ■ | J24: =IFERROR(IF(OR($A24="",$A24="Model",LEFT($A24,5)="Markt"),"",IF(AND($C24<=J$3+6,$D24>=J$3),"■","")),"") -> ■ | K24: =IFERROR(IF(OR($A24="",$A24="Model",LEFT($A24,5)="Markt"),"",IF(AND($C24<=K$3+6,$D24>=K$3),"■","")),"") -> ■ | L24: =IFERROR(IF(OR($A24="",$A24="Model",LEFT($A24,5)="Markt"),"",IF(AND($C24<=L$3+6,$D24>=L$3),"■","")),"") -> ■ | ... V24: =IFERROR(IF(OR($A24="",$A24="Model",LEFT($A24,5)="Markt"),"",IF(AND($C24<=V$3+6,$D24>=V$3),"■","")),"") -> ■ | X24: Cayenne E3 II | Y24: 20130912_20130912_POR_RNG_RNG_DEU_T1_NU_EUR_2026-02-22_2026-12-30_LOCAL-AOPROGRAMMATICPERFORMANCE2026 | Z24: 46075 | AA24: 46202 | AB24: =IF(AND($Z24<=(AB$3+6),$AA24>=AB$3),"■","") -> ■ | AC24: =IF(AND($Z24<=(AC$3+6),$AA24>=AC$3),"■","") -> ■ | AD24: =IF(AND($Z24<=(AD$3+6),$AA24>=AD$3),"■","") -> ■ | AE24: =IF(AND($Z24<=(AE$3+6),$AA24>=AE$3),"■","") -> ■ | AF24: =IF(AND($Z24<=(AF$3+6),$AA24>=AF$3),"■","") -> ■ | AG24: =IF(AND($Z24<=(AG$3+6),$AA24>=AG$3),"■","") -> ■ | AH24: =IF(AND($Z24<=(AH$3+6),$AA24>=AH$3),"■","") -> ■ | AI24: =IF(AND($Z24<=(AI$3+6),$AA24>=AI$3),"■","") -> ■ | ... AS24: =IF(AND($Z24<=(AS$3+6),$AA24>=AS$3),"■","") | AT24: Programmatic | AU24: 185000 € (HY2 is not yet planned out but a separate budget is allocated for it) | AV24: Dealer contact form submitted (DCFS) | AW24: Complex Audience Setup including Prospecting and LAL and Retargeting Audiences / see above
A25: Cayenne E3 II | B25: Paid Social | C25: 46204 | D25: 46264 | E25: =IFERROR(IF(OR($A25="",$A25="Model",LEFT($A25,5)="Markt"),"",IF(AND($C25<=E$3+6,$D25>=E$3),"■","")),"") | F25: =IFERROR(IF(OR($A25="",$A25="Model",LEFT($A25,5)="Markt"),"",IF(AND($C25<=F$3+6,$D25>=F$3),"■","")),"") | G25: =IFERROR(IF(OR($A25="",$A25="Model",LEFT($A25,5)="Markt"),"",IF(AND($C25<=G$3+6,$D25>=G$3),"■","")),"") | H25: =IFERROR(IF(OR($A25="",$A25="Model",LEFT($A25,5)="Markt"),"",IF(AND($C25<=H$3+6,$D25>=H$3),"■","")),"") | I25: =IFERROR(IF(OR($A25="",$A25="Model",LEFT($A25,5)="Markt"),"",IF(AND($C25<=I$3+6,$D25>=I$3),"■","")),"") | J25: =IFERROR(IF(OR($A25="",$A25="Model",LEFT($A25,5)="Markt"),"",IF(AND($C25<=J$3+6,$D25>=J$3),"■","")),"") | K25: =IFERROR(IF(OR($A25="",$A25="Model",LEFT($A25,5)="Markt"),"",IF(AND($C25<=K$3+6,$D25>=K$3),"■","")),"") | L25: =IFERROR(IF(OR($A25="",$A25="Model",LEFT($A25,5)="Markt"),"",IF(AND($C25<=L$3+6,$D25>=L$3),"■","")),"") | ... V25: =IFERROR(IF(OR($A25="",$A25="Model",LEFT($A25,5)="Markt"),"",IF(AND($C25<=V$3+6,$D25>=V$3),"■","")),"") -> ■ | X25: Cayenne E3 II | Y25: 20205848_20205848_POR_CAY_SUV_DEU_T1_NU_EUR_2025-12-31_2026-12-30_LOCAL-CAYENNEE4CAYENNEFAMILY | Z25: 46159 | AA25: 46200 | AB25: =IF(AND($Z25<=(AB$3+6),$AA25>=AB$3),"■","") | AC25: =IF(AND($Z25<=(AC$3+6),$AA25>=AC$3),"■","") | AD25: =IF(AND($Z25<=(AD$3+6),$AA25>=AD$3),"■","") -> ■ | AE25: =IF(AND($Z25<=(AE$3+6),$AA25>=AE$3),"■","") -> ■ | AF25: =IF(AND($Z25<=(AF$3+6),$AA25>=AF$3),"■","") -> ■ | AG25: =IF(AND($Z25<=(AG$3+6),$AA25>=AG$3),"■","") -> ■ | AH25: =IF(AND($Z25<=(AH$3+6),$AA25>=AH$3),"■","") -> ■ | AI25: =IF(AND($Z25<=(AI$3+6),$AA25>=AI$3),"■","") -> ■ | ... AS25: =IF(AND($Z25<=(AS$3+6),$AA25>=AS$3),"■","") | AT25: Programmatic | AU25: 70000 | AV25: Configuration | AW25: tbd / tbd
A26: Cayenne E4 | B26: Google Ads | C26: 46143 | D26: 46264 | E26: =IFERROR(IF(OR($A26="",$A26="Model",LEFT($A26,5)="Markt"),"",IF(AND($C26<=E$3+6,$D26>=E$3),"■","")),"") -> ■ | F26: =IFERROR(IF(OR($A26="",$A26="Model",LEFT($A26,5)="Markt"),"",IF(AND($C26<=F$3+6,$D26>=F$3),"■","")),"") -> ■ | G26: =IFERROR(IF(OR($A26="",$A26="Model",LEFT($A26,5)="Markt"),"",IF(AND($C26<=G$3+6,$D26>=G$3),"■","")),"") -> ■ | H26: =IFERROR(IF(OR($A26="",$A26="Model",LEFT($A26,5)="Markt"),"",IF(AND($C26<=H$3+6,$D26>=H$3),"■","")),"") -> ■ | I26: =IFERROR(IF(OR($A26="",$A26="Model",LEFT($A26,5)="Markt"),"",IF(AND($C26<=I$3+6,$D26>=I$3),"■","")),"") -> ■ | J26: =IFERROR(IF(OR($A26="",$A26="Model",LEFT($A26,5)="Markt"),"",IF(AND($C26<=J$3+6,$D26>=J$3),"■","")),"") -> ■ | K26: =IFERROR(IF(OR($A26="",$A26="Model",LEFT($A26,5)="Markt"),"",IF(AND($C26<=K$3+6,$D26>=K$3),"■","")),"") -> ■ | L26: =IFERROR(IF(OR($A26="",$A26="Model",LEFT($A26,5)="Markt"),"",IF(AND($C26<=L$3+6,$D26>=L$3),"■","")),"") -> ■ | ... V26: =IFERROR(IF(OR($A26="",$A26="Model",LEFT($A26,5)="Markt"),"",IF(AND($C26<=V$3+6,$D26>=V$3),"■","")),"") -> ■ | X26: Cayenne E4 | Y26: 20056448_20056448_POR_RNG_RNG_DEU_T1_NU_EUR_2025-12-31_2026-12-30_LOCAL-SEANATIONAL2026 | Z26: 46026 | AA26: 46386 | AB26: =IF(AND($Z26<=(AB$3+6),$AA26>=AB$3),"■","") -> ■ | AC26: =IF(AND($Z26<=(AC$3+6),$AA26>=AC$3),"■","") -> ■ | AD26: =IF(AND($Z26<=(AD$3+6),$AA26>=AD$3),"■","") -> ■ | AE26: =IF(AND($Z26<=(AE$3+6),$AA26>=AE$3),"■","") -> ■ | AF26: =IF(AND($Z26<=(AF$3+6),$AA26>=AF$3),"■","") -> ■ | AG26: =IF(AND($Z26<=(AG$3+6),$AA26>=AG$3),"■","") -> ■ | AH26: =IF(AND($Z26<=(AH$3+6),$AA26>=AH$3),"■","") -> ■ | AI26: =IF(AND($Z26<=(AI$3+6),$AA26>=AI$3),"■","") -> ■ | ... AS26: =IF(AND($Z26<=(AS$3+6),$AA26>=AS$3),"■","") -> ■ | AT26: Search | AU26: 146000 | AV26: Dealer contact form submitted (DCFS) | AW26: Keyword Targeting / see above
A27: Cayenne E4 | B27: META Inventory Ads | C27: 46204 | D27: 46264 | E27: =IFERROR(IF(OR($A27="",$A27="Model",LEFT($A27,5)="Markt"),"",IF(AND($C27<=E$3+6,$D27>=E$3),"■","")),"") | F27: =IFERROR(IF(OR($A27="",$A27="Model",LEFT($A27,5)="Markt"),"",IF(AND($C27<=F$3+6,$D27>=F$3),"■","")),"") | G27: =IFERROR(IF(OR($A27="",$A27="Model",LEFT($A27,5)="Markt"),"",IF(AND($C27<=G$3+6,$D27>=G$3),"■","")),"") | H27: =IFERROR(IF(OR($A27="",$A27="Model",LEFT($A27,5)="Markt"),"",IF(AND($C27<=H$3+6,$D27>=H$3),"■","")),"") | I27: =IFERROR(IF(OR($A27="",$A27="Model",LEFT($A27,5)="Markt"),"",IF(AND($C27<=I$3+6,$D27>=I$3),"■","")),"") | J27: =IFERROR(IF(OR($A27="",$A27="Model",LEFT($A27,5)="Markt"),"",IF(AND($C27<=J$3+6,$D27>=J$3),"■","")),"") | K27: =IFERROR(IF(OR($A27="",$A27="Model",LEFT($A27,5)="Markt"),"",IF(AND($C27<=K$3+6,$D27>=K$3),"■","")),"") | L27: =IFERROR(IF(OR($A27="",$A27="Model",LEFT($A27,5)="Markt"),"",IF(AND($C27<=L$3+6,$D27>=L$3),"■","")),"") | ... V27: =IFERROR(IF(OR($A27="",$A27="Model",LEFT($A27,5)="Markt"),"",IF(AND($C27<=V$3+6,$D27>=V$3),"■","")),"") -> ■ | X27: Cayenne E4 | Y27: 20130912_20130912_POR_RNG_RNG_DEU_T1_NU_EUR_2026-02-22_2026-12-30_LOCAL-AOPROGRAMMATICPERFORMANCE2026 | Z27: 46075 | AA27: 46325 | AB27: =IF(AND($Z27<=(AB$3+6),$AA27>=AB$3),"■","") -> ■ | AC27: =IF(AND($Z27<=(AC$3+6),$AA27>=AC$3),"■","") -> ■ | AD27: =IF(AND($Z27<=(AD$3+6),$AA27>=AD$3),"■","") -> ■ | AE27: =IF(AND($Z27<=(AE$3+6),$AA27>=AE$3),"■","") -> ■ | AF27: =IF(AND($Z27<=(AF$3+6),$AA27>=AF$3),"■","") -> ■ | AG27: =IF(AND($Z27<=(AG$3+6),$AA27>=AG$3),"■","") -> ■ | AH27: =IF(AND($Z27<=(AH$3+6),$AA27>=AH$3),"■","") -> ■ | AI27: =IF(AND($Z27<=(AI$3+6),$AA27>=AI$3),"■","") -> ■ | ... AS27: =IF(AND($Z27<=(AS$3+6),$AA27>=AS$3),"■","") -> ■ | AT27: Programmatic | AU27: 190000 | AV27: Dealer contact form submitted (DCFS) | AW27: Complex Audience Setup including Prosecting LAL and Retargeting Audiences / see above
A28: Cayenne E4 | B28: Paid Social | C28: 46204 | D28: 46264 | E28: =IFERROR(IF(OR($A28="",$A28="Model",LEFT($A28,5)="Markt"),"",IF(AND($C28<=E$3+6,$D28>=E$3),"■","")),"") | F28: =IFERROR(IF(OR($A28="",$A28="Model",LEFT($A28,5)="Markt"),"",IF(AND($C28<=F$3+6,$D28>=F$3),"■","")),"") | G28: =IFERROR(IF(OR($A28="",$A28="Model",LEFT($A28,5)="Markt"),"",IF(AND($C28<=G$3+6,$D28>=G$3),"■","")),"") | H28: =IFERROR(IF(OR($A28="",$A28="Model",LEFT($A28,5)="Markt"),"",IF(AND($C28<=H$3+6,$D28>=H$3),"■","")),"") | I28: =IFERROR(IF(OR($A28="",$A28="Model",LEFT($A28,5)="Markt"),"",IF(AND($C28<=I$3+6,$D28>=I$3),"■","")),"") | J28: =IFERROR(IF(OR($A28="",$A28="Model",LEFT($A28,5)="Markt"),"",IF(AND($C28<=J$3+6,$D28>=J$3),"■","")),"") | K28: =IFERROR(IF(OR($A28="",$A28="Model",LEFT($A28,5)="Markt"),"",IF(AND($C28<=K$3+6,$D28>=K$3),"■","")),"") | L28: =IFERROR(IF(OR($A28="",$A28="Model",LEFT($A28,5)="Markt"),"",IF(AND($C28<=L$3+6,$D28>=L$3),"■","")),"") | ... V28: =IFERROR(IF(OR($A28="",$A28="Model",LEFT($A28,5)="Markt"),"",IF(AND($C28<=V$3+6,$D28>=V$3),"■","")),"") -> ■ | X28: Cayenne E4 | Y28: 20205848_20205848_POR_CAY_SUV_DEU_T1_NU_EUR_2025-12-31_2026-12-30_LOCAL-CAYENNEE4CAYENNEFAMILY | Z28: 46159 | AA28: 46200 | AB28: =IF(AND($Z28<=(AB$3+6),$AA28>=AB$3),"■","") | AC28: =IF(AND($Z28<=(AC$3+6),$AA28>=AC$3),"■","") | AD28: =IF(AND($Z28<=(AD$3+6),$AA28>=AD$3),"■","") -> ■ | AE28: =IF(AND($Z28<=(AE$3+6),$AA28>=AE$3),"■","") -> ■ | AF28: =IF(AND($Z28<=(AF$3+6),$AA28>=AF$3),"■","") -> ■ | AG28: =IF(AND($Z28<=(AG$3+6),$AA28>=AG$3),"■","") -> ■ | AH28: =IF(AND($Z28<=(AH$3+6),$AA28>=AH$3),"■","") -> ■ | AI28: =IF(AND($Z28<=(AI$3+6),$AA28>=AI$3),"■","") -> ■ | ... AS28: =IF(AND($Z28<=(AS$3+6),$AA28>=AS$3),"■","") | AT28: Programmatic | AU28: 70000 | AV28: Configuration | AW28: tbd / tbd
A29: Markt: PKO | X29: Markt: PKO (Survey)
A30: Model | B30: CTG Measure | C30: Start | D30: Ende | E30: CW18 | F30: CW19 | G30: CW20 | H30: CW21 | I30: CW22 | J30: CW23 | K30: CW24 | L30: CW25 | M30: CW26 | N30: CW27 | O30: CW28 | P30: CW29 | Q30: CW30 | R30: CW31 | S30: CW32 | T30: CW33 | U30: CW34 | V30: CW35 | X30: Model | Y30: Local Measure | Z30: Start | AA30: Ende | AB30: CW18 | AC30: CW19 | AD30: CW20 | AE30: CW21 | AF30: CW22 | AG30: CW23 | AH30: CW24 | AI30: CW25 | AJ30: CW26 | AK30: CW27 | AL30: CW28 | AM30: CW29 | AN30: CW30 | AO30: CW31 | AP30: CW32 | AQ30: CW33 | AR30: CW34 | AS30: CW35 | AT30: Channel | AU30: Budget | AV30: KPI | AW30: Audience
A31: Macan BEV | B31: Google Ads | C31: 46143 | D31: 46264 | E31: =IFERROR(IF(OR($A31="",$A31="Model",LEFT($A31,5)="Markt"),"",IF(AND($C31<=E$3+6,$D31>=E$3),"■","")),"") -> ■ | F31: =IFERROR(IF(OR($A31="",$A31="Model",LEFT($A31,5)="Markt"),"",IF(AND($C31<=F$3+6,$D31>=F$3),"■","")),"") -> ■ | G31: =IFERROR(IF(OR($A31="",$A31="Model",LEFT($A31,5)="Markt"),"",IF(AND($C31<=G$3+6,$D31>=G$3),"■","")),"") -> ■ | H31: =IFERROR(IF(OR($A31="",$A31="Model",LEFT($A31,5)="Markt"),"",IF(AND($C31<=H$3+6,$D31>=H$3),"■","")),"") -> ■ | I31: =IFERROR(IF(OR($A31="",$A31="Model",LEFT($A31,5)="Markt"),"",IF(AND($C31<=I$3+6,$D31>=I$3),"■","")),"") -> ■ | J31: =IFERROR(IF(OR($A31="",$A31="Model",LEFT($A31,5)="Markt"),"",IF(AND($C31<=J$3+6,$D31>=J$3),"■","")),"") -> ■ | K31: =IFERROR(IF(OR($A31="",$A31="Model",LEFT($A31,5)="Markt"),"",IF(AND($C31<=K$3+6,$D31>=K$3),"■","")),"") -> ■ | L31: =IFERROR(IF(OR($A31="",$A31="Model",LEFT($A31,5)="Markt"),"",IF(AND($C31<=L$3+6,$D31>=L$3),"■","")),"") -> ■ | ... V31: =IFERROR(IF(OR($A31="",$A31="Model",LEFT($A31,5)="Markt"),"",IF(AND($C31<=V$3+6,$D31>=V$3),"■","")),"") -> ■ | X31: Macan H2 | Y31: H2 GTS | Z31: 46165.917 | AA31: 46202.917 | AB31: =IF(AND($Z31<=(AB$3+6),$AA31>=AB$3),"■","") | AC31: =IF(AND($Z31<=(AC$3+6),$AA31>=AC$3),"■","") | AD31: =IF(AND($Z31<=(AD$3+6),$AA31>=AD$3),"■","") | AE31: =IF(AND($Z31<=(AE$3+6),$AA31>=AE$3),"■","") -> ■ | AF31: =IF(AND($Z31<=(AF$3+6),$AA31>=AF$3),"■","") -> ■ | AG31: =IF(AND($Z31<=(AG$3+6),$AA31>=AG$3),"■","") -> ■ | AH31: =IF(AND($Z31<=(AH$3+6),$AA31>=AH$3),"■","") -> ■ | AI31: =IF(AND($Z31<=(AI$3+6),$AA31>=AI$3),"■","") -> ■ | ... AS31: =IF(AND($Z31<=(AS$3+6),$AA31>=AS$3),"■","") | AT31: Social,Search,Programmatic,Other Online Channel | AU31: 350,000,000KRW | AV31: Configuration,Dealer contact form submitted (DCFS) | AW31: Existing Buyers / All Strategic Target Groups
A32: Macan BEV | B32: Google Inventory Ads | C32: 46143 | D32: 46264 | E32: =IFERROR(IF(OR($A32="",$A32="Model",LEFT($A32,5)="Markt"),"",IF(AND($C32<=E$3+6,$D32>=E$3),"■","")),"") -> ■ | F32: =IFERROR(IF(OR($A32="",$A32="Model",LEFT($A32,5)="Markt"),"",IF(AND($C32<=F$3+6,$D32>=F$3),"■","")),"") -> ■ | G32: =IFERROR(IF(OR($A32="",$A32="Model",LEFT($A32,5)="Markt"),"",IF(AND($C32<=G$3+6,$D32>=G$3),"■","")),"") -> ■ | H32: =IFERROR(IF(OR($A32="",$A32="Model",LEFT($A32,5)="Markt"),"",IF(AND($C32<=H$3+6,$D32>=H$3),"■","")),"") -> ■ | I32: =IFERROR(IF(OR($A32="",$A32="Model",LEFT($A32,5)="Markt"),"",IF(AND($C32<=I$3+6,$D32>=I$3),"■","")),"") -> ■ | J32: =IFERROR(IF(OR($A32="",$A32="Model",LEFT($A32,5)="Markt"),"",IF(AND($C32<=J$3+6,$D32>=J$3),"■","")),"") -> ■ | K32: =IFERROR(IF(OR($A32="",$A32="Model",LEFT($A32,5)="Markt"),"",IF(AND($C32<=K$3+6,$D32>=K$3),"■","")),"") -> ■ | L32: =IFERROR(IF(OR($A32="",$A32="Model",LEFT($A32,5)="Markt"),"",IF(AND($C32<=L$3+6,$D32>=L$3),"■","")),"") -> ■ | ... V32: =IFERROR(IF(OR($A32="",$A32="Model",LEFT($A32,5)="Markt"),"",IF(AND($C32<=V$3+6,$D32>=V$3),"■","")),"") -> ■ | X32: Cayenne E4 | Y32: E4 Pre Launch | Z32: 46100.958 | AA32: 46145.917 | AB32: =IF(AND($Z32<=(AB$3+6),$AA32>=AB$3),"■","") -> ■ | AC32: =IF(AND($Z32<=(AC$3+6),$AA32>=AC$3),"■","") | AD32: =IF(AND($Z32<=(AD$3+6),$AA32>=AD$3),"■","") | AE32: =IF(AND($Z32<=(AE$3+6),$AA32>=AE$3),"■","") | AF32: =IF(AND($Z32<=(AF$3+6),$AA32>=AF$3),"■","") | AG32: =IF(AND($Z32<=(AG$3+6),$AA32>=AG$3),"■","") | AH32: =IF(AND($Z32<=(AH$3+6),$AA32>=AH$3),"■","") | AI32: =IF(AND($Z32<=(AI$3+6),$AA32>=AI$3),"■","") | ... AS32: =IF(AND($Z32<=(AS$3+6),$AA32>=AS$3),"■","") | AT32: Social,Search,Programmatic,Other Online Channel | AU32: 1,480,000,000KRW | AV32: Impressions | AW32: Existing Buyers / All strategic target groups
A33: Macan BEV | B33: META Inventory Ads | C33: 46143 | D33: 46264 | E33: =IFERROR(IF(OR($A33="",$A33="Model",LEFT($A33,5)="Markt"),"",IF(AND($C33<=E$3+6,$D33>=E$3),"■","")),"") -> ■ | F33: =IFERROR(IF(OR($A33="",$A33="Model",LEFT($A33,5)="Markt"),"",IF(AND($C33<=F$3+6,$D33>=F$3),"■","")),"") -> ■ | G33: =IFERROR(IF(OR($A33="",$A33="Model",LEFT($A33,5)="Markt"),"",IF(AND($C33<=G$3+6,$D33>=G$3),"■","")),"") -> ■ | H33: =IFERROR(IF(OR($A33="",$A33="Model",LEFT($A33,5)="Markt"),"",IF(AND($C33<=H$3+6,$D33>=H$3),"■","")),"") -> ■ | I33: =IFERROR(IF(OR($A33="",$A33="Model",LEFT($A33,5)="Markt"),"",IF(AND($C33<=I$3+6,$D33>=I$3),"■","")),"") -> ■ | J33: =IFERROR(IF(OR($A33="",$A33="Model",LEFT($A33,5)="Markt"),"",IF(AND($C33<=J$3+6,$D33>=J$3),"■","")),"") -> ■ | K33: =IFERROR(IF(OR($A33="",$A33="Model",LEFT($A33,5)="Markt"),"",IF(AND($C33<=K$3+6,$D33>=K$3),"■","")),"") -> ■ | L33: =IFERROR(IF(OR($A33="",$A33="Model",LEFT($A33,5)="Markt"),"",IF(AND($C33<=L$3+6,$D33>=L$3),"■","")),"") -> ■ | ... V33: =IFERROR(IF(OR($A33="",$A33="Model",LEFT($A33,5)="Markt"),"",IF(AND($C33<=V$3+6,$D33>=V$3),"■","")),"") -> ■ | X33: Cayenne E4 | Y33: E4 Coupe Launch | Z33: 46165.917 | AA33: 46202.917 | AB33: =IF(AND($Z33<=(AB$3+6),$AA33>=AB$3),"■","") | AC33: =IF(AND($Z33<=(AC$3+6),$AA33>=AC$3),"■","") | AD33: =IF(AND($Z33<=(AD$3+6),$AA33>=AD$3),"■","") | AE33: =IF(AND($Z33<=(AE$3+6),$AA33>=AE$3),"■","") -> ■ | AF33: =IF(AND($Z33<=(AF$3+6),$AA33>=AF$3),"■","") -> ■ | AG33: =IF(AND($Z33<=(AG$3+6),$AA33>=AG$3),"■","") -> ■ | AH33: =IF(AND($Z33<=(AH$3+6),$AA33>=AH$3),"■","") -> ■ | AI33: =IF(AND($Z33<=(AI$3+6),$AA33>=AI$3),"■","") -> ■ | ... AS33: =IF(AND($Z33<=(AS$3+6),$AA33>=AS$3),"■","") | AT33: Social,Search,Programmatic,Other Online Channel | AU33: 500,000,000 KRW | AV33: Configuration,Dealer contact form submitted (DCFS) | AW33: Existing Buyers / All Strategic Target Groups
